/Users/kundan.jha/KnowledgeAI/scripts/agents/shared.py:9: LangChainDeprecationWarning: The class `Chroma` was deprecated in LangChain 0.2.9 and will be removed in 1.0. An updated version of the class exists in the :class:`~langchain-chroma package and should be used instead. To use it run `pip install -U :class:`~langchain-chroma` and import as `from :class:`~langchain_chroma import Chroma``.
  vectordb = Chroma(
2025-07-22 20:06:08,443 INFO     chromadb.telemetry.product.posthog | Anonymized telemetry enabled. See                     https://docs.trychroma.com/telemetry for more information.
INFO:     Started server process [49752]
INFO:     Waiting for application startup.
INFO:     Application startup complete.
INFO:     Uvicorn running on http://127.0.0.1:9133 (Press CTRL+C to quit)
2025-07-22 20:41:34,781 INFO     root | ðŸ›‘ Ticket agent shutting down.
ERROR:    Traceback (most recent call last):
  File "/Users/kundan.jha/miniforge/envs/knowledge-ai/lib/python3.12/asyncio/runners.py", line 195, in run
    return runner.run(main)
           ^^^^^^^^^^^^^^^^
  File "/Users/kundan.jha/miniforge/envs/knowledge-ai/lib/python3.12/asyncio/runners.py", line 118, in run
    return self._loop.run_until_complete(task)
           ^^^^^^^^^^^^^^^^^^^^^^^^^^^^^^^^^^^
  File "uvloop/loop.pyx", line 1512, in uvloop.loop.Loop.run_until_complete
  File "uvloop/loop.pyx", line 1505, in uvloop.loop.Loop.run_until_complete
  File "uvloop/loop.pyx", line 1379, in uvloop.loop.Loop.run_forever
  File "uvloop/loop.pyx", line 557, in uvloop.loop.Loop._run
  File "uvloop/handles/poll.pyx", line 216, in uvloop.loop.__on_uvpoll_event
  File "uvloop/cbhandles.pyx", line 83, in uvloop.loop.Handle._run
  File "uvloop/cbhandles.pyx", line 66, in uvloop.loop.Handle._run
  File "uvloop/loop.pyx", line 399, in uvloop.loop.Loop._read_from_self
  File "uvloop/loop.pyx", line 404, in uvloop.loop.Loop._invoke_signals
  File "uvloop/loop.pyx", line 379, in uvloop.loop.Loop._ceval_process_signals
  File "/Users/kundan.jha/KnowledgeAI/scripts/agents/ticket_agent.py", line 10, in handle_shutdown
    sys.exit(0)
SystemExit: 0

During handling of the above exception, another exception occurred:

Traceback (most recent call last):
  File "/Users/kundan.jha/miniforge/envs/knowledge-ai/lib/python3.12/site-packages/starlette/routing.py", line 701, in lifespan
    await receive()
  File "/Users/kundan.jha/miniforge/envs/knowledge-ai/lib/python3.12/site-packages/uvicorn/lifespan/on.py", line 137, in receive
    return await self.receive_queue.get()
           ^^^^^^^^^^^^^^^^^^^^^^^^^^^^^^
  File "/Users/kundan.jha/miniforge/envs/knowledge-ai/lib/python3.12/asyncio/queues.py", line 158, in get
    await getter
asyncio.exceptions.CancelledError

